Workbook

Sheet Sheet1
A1: 姓名 | B1: 學校 | C1: 類組 | D1: 模考1_國文 | E1: 模考1_英文 | F1: 模考1_數學 | G1: 模考1_自然 | H1: 模考1_社會 | I1: 模考2_國文 | J1: 模考2_英文 | K1: 模考2_數A | L1: 模考2_數B | M1: 模考2_自然 | N1: 模考2_社會 | O1: 學測_國文 | P1: 學測_英文 | Q1: 學測_數A | R1: 學測_數B | S1: 學測_自然 | T1: 學測_社會
A2: 楊博凱 | B2: 陽明高中 | C2: 文組 | D2: {=_xlfn.XLOOKUP(A2,'[1]第一次落點分析 '!$B:$B,'[1]第一次落點分析 '!$C:$G,"")} -> 10 | E2: 6 | F2: 6 | G2: － | H2: 10 | I2: {=_xlfn.XLOOKUP(A2,[1]第二次落點分析!$B:$B,[1]第二次落點分析!$C:$H,"")} -> 11 | J2: 10 | K2: 7 | L2: 9 | M2: － | N2: 13 | O2: {=_xlfn.XLOOKUP(A2,'[1]113學測'!$B:$B,'[1]113學測'!$C:$H,"")} -> 11 | P2: 7 | Q2: 6 | R2: 9 | S2: 0 | T2: 14
A3: 郭力綸 | B3: 成淵高中 | C3: 理組 | D3: {=_xlfn.XLOOKUP(A3,'[1]第一次落點分析 '!$B:$B,'[1]第一次落點分析 '!$C:$G,"")} -> 10 | E3: 10 | F3: 13 | G3: 15 | H3: － | I3: {=_xlfn.XLOOKUP(A3,[1]第二次落點分析!$B:$B,[1]第二次落點分析!$C:$H,"")} -> 9 | J3: 13 | K3: 14 | L3: － | M3: 13 | N3: － | O3: {=_xlfn.XLOOKUP(A3,'[1]113學測'!$B:$B,'[1]113學測'!$C:$H,"")} -> 11 | P3: 11 | Q3: 13 | R3: 0 | S3: 14 | T3: 0
A4: 王宥惟 | B4: 成淵高中 | C4: 理組 | D4: {=_xlfn.XLOOKUP(A4,'[1]第一次落點分析 '!$B:$B,'[1]第一次落點分析 '!$C:$G,"")} -> 11 | E4: 5 | F4: 10 | G4: － | H4: 13 | I4: {=_xlfn.XLOOKUP(A4,[1]第二次落點分析!$B:$B,[1]第二次落點分析!$C:$H,"")} -> 12 | J4: 7 | K4: 9 | L4: 12 | M4: － | N4: 14 | O4: {=_xlfn.XLOOKUP(A4,'[1]113學測'!$B:$B,'[1]113學測'!$C:$H,"")} -> 12 | P4: 8 | Q4: 10 | R4: 11 | S4: 0 | T4: 12
A5: 陳柔臻 | B5: 大直高中 | C5: 理組 | D5: {=_xlfn.XLOOKUP(A5,'[1]第一次落點分析 '!$B:$B,'[1]第一次落點分析 '!$C:$G,"")} -> 11 | E5: 5 | F5: 8 | G5: 8 | H5: － | I5: {=_xlfn.XLOOKUP(A5,[1]第二次落點分析!$B:$B,[1]第二次落點分析!$C:$H,"")} -> 12 | J5: 8 | K5: 9 | L5: － | M5: 11 | N5: － | O5: {=_xlfn.XLOOKUP(A5,'[1]113學測'!$B:$B,'[1]113學測'!$C:$H,"")} -> 12 | P5: 9 | Q5: 6 | R5: 7 | S5: 10 | T5: 11
A6: 周睿紘 | B6: 成淵高中 | C6: 理組 | D6: {=_xlfn.XLOOKUP(A6,'[1]第一次落點分析 '!$B:$B,'[1]第一次落點分析 '!$C:$G,"")} -> 9 | E6: 6 | F6: 13 | G6: 9 | H6: － | I6: {=_xlfn.XLOOKUP(A6,[1]第二次落點分析!$B:$B,[1]第二次落點分析!$C:$H,"")} -> 8 | J6: 8 | K6: 9 | L6: － | M6: 9 | N6: － | O6: {=_xlfn.XLOOKUP(A6,'[1]113學測'!$B:$B,'[1]113學測'!$C:$H,"")} -> 11 | P6: 7 | Q6: 11 | R6: 9 | S6: 12 | T6: 0
A7: 林承翰 | B7: 大直高中 | C7: 理組 | D7: {=_xlfn.XLOOKUP(A7,'[1]第一次落點分析 '!$B:$B,'[1]第一次落點分析 '!$C:$G,"")} -> 9 | E7: 14 | F7: 8 | G7: 9 | H7: 12 | I7: {=_xlfn.XLOOKUP(A7,[1]第二次落點分析!$B:$B,[1]第二次落點分析!$C:$H,"")} -> 13 | J7: 14 | K7: 8 | L7: － | M7: 8 | N7: 12 | O7: {=_xlfn.XLOOKUP(A7,'[1]113學測'!$B:$B,'[1]113學測'!$C:$H,"")} -> 13 | P7: 14 | Q7: 6 | R7: 10 | S7: 9 | T7: 11
A8: 鄭芷欣 | B8: 成淵高中 | C8: 理組 | D8: {=_xlfn.XLOOKUP(A8,'[1]第一次落點分析 '!$B:$B,'[1]第一次落點分析 '!$C:$G,"")} -> 12 | E8: 7 | F8: 12 | G8: 11 | H8: － | I8: {=_xlfn.XLOOKUP(A8,[1]第二次落點分析!$B:$B,[1]第二次落點分析!$C:$H,"")} -> 13 | J8: 10 | K8: 10 | L8: － | M8: 11 | N8: － | O8: {=_xlfn.XLOOKUP(A8,'[1]113學測'!$B:$B,'[1]113學測'!$C:$H,"")} -> 13 | P8: 8 | Q8: 9 | R8: 11 | S8: 11 | T8: 10
A9: 朱迎甄 | B9: 百齡高中 | C9: 文組 | D9: {=_xlfn.XLOOKUP(A9,'[1]第一次落點分析 '!$B:$B,'[1]第一次落點分析 '!$C:$G,"")} -> 13 | E9: 9 | F9: 5 | G9: 0 | H9: 11 | I9: {=_xlfn.XLOOKUP(A9,[1]第二次落點分析!$B:$B,[1]第二次落點分析!$C:$H,"")} -> 11 | J9: 10 | K9: 6 | L9: 7 | M9: － | N9: 12 | O9: {=_xlfn.XLOOKUP(A9,'[1]113學測'!$B:$B,'[1]113學測'!$C:$H,"")} -> 11 | P9: 10 | Q9: 6 | R9: 6 | S9: 0 | T9: 13
A10: 龔韋任 | B10: 松山高中 | C10: 理組 | D10: {=_xlfn.XLOOKUP(A10,'[1]第一次落點分析 '!$B:$B,'[1]第一次落點分析 '!$C:$G,"")} -> 13 | E10: 11 | F10: 15 | G10: 14 | H10: 8 | I10: {=_xlfn.XLOOKUP(A10,[1]第二次落點分析!$B:$B,[1]第二次落點分析!$C:$H,"")} -> 13 | J10: 13 | K10: 12 | L10: 13 | M10: 14 | N10: － | O10: {=_xlfn.XLOOKUP(A10,'[1]113學測'!$B:$B,'[1]113學測'!$C:$H,"")} -> 12 | P10: 12 | Q10: 13 | R10: 15 | S10: 15 | T10: 10
A11: 陳香妤 | B11: 內湖高中 | C11: 文組 | D11: {=_xlfn.XLOOKUP(A11,'[1]第一次落點分析 '!$B:$B,'[1]第一次落點分析 '!$C:$G,"")} -> 11 | E11: 12 | F11: 8 | G11: 8 | H11: 13 | I11: {=_xlfn.XLOOKUP(A11,[1]第二次落點分析!$B:$B,[1]第二次落點分析!$C:$H,"")} -> 12 | J11: 14 | K11: 6 | L11: 10 | M11: 7 | N11: 14 | O11: {=_xlfn.XLOOKUP(A11,'[1]113學測'!$B:$B,'[1]113學測'!$C:$H,"")} -> 12 | P11: 13 | Q11: 6 | R11: 8 | S11: 7 | T11: 12
A12: 王勝暉 | B12: 百齡高中 | C12: 理組 | D12: {=_xlfn.XLOOKUP(A12,'[1]第一次落點分析 '!$B:$B,'[1]第一次落點分析 '!$C:$G,"")} -> 11 | E12: 9 | F12: 9 | G12: 11 | H12: － | I12: {=_xlfn.XLOOKUP(A12,[1]第二次落點分析!$B:$B,[1]第二次落點分析!$C:$H,"")} -> 12 | J12: 11 | K12: 14 | L12: 12 | M12: 10 | N12: 8 | O12: {=_xlfn.XLOOKUP(A12,'[1]113學測'!$B:$B,'[1]113學測'!$C:$H,"")} -> 10 | P12: 9 | Q12: 13 | R12: 12 | S12: 12 | T12: 8
A13: 林恩頡 | B13: 中正高中 | C13: 理組 | D13: {=_xlfn.XLOOKUP(A13,'[1]第一次落點分析 '!$B:$B,'[1]第一次落點分析 '!$C:$G,"")} -> 13 | E13: 9 | F13: 11 | G13: 10 | H13: 5 | I13: {=_xlfn.XLOOKUP(A13,[1]第二次落點分析!$B:$B,[1]第二次落點分析!$C:$H,"")} -> 10 | J13: 11 | K13: 10 | L13: － | M13: 8 | N13: － | O13: {=_xlfn.XLOOKUP(A13,'[1]113學測'!$B:$B,'[1]113學測'!$C:$H,"")} -> 10 | P13: 10 | Q13: 12 | R13: 13 | S13: 12 | T13: 10
A14: 陳昱安 | B14: 成淵高中 | C14: 理組 | D14: {=_xlfn.XLOOKUP(A14,'[1]第一次落點分析 '!$B:$B,'[1]第一次落點分析 '!$C:$G,"")} -> 10 | E14: 8 | F14: 11 | G14: 9 | H14: － | I14: {=_xlfn.XLOOKUP(A14,[1]第二次落點分析!$B:$B,[1]第二次落點分析!$C:$H,"")} -> 10 | J14: 9 | K14: 13 | L14: － | M14: 11 | N14: － | O14: {=_xlfn.XLOOKUP(A14,'[1]113學測'!$B:$B,'[1]113學測'!$C:$H,"")} -> 12 | P14: 10 | Q14: 14 | R14: 13 | S14: 13 | T14: 8
A15: 陳渼錞 | B15: 復興高中 | C15: 理組 | D15: {=_xlfn.XLOOKUP(A15,'[1]第一次落點分析 '!$B:$B,'[1]第一次落點分析 '!$C:$G,"")} -> 12 | E15: 8 | F15: 8 | G15: 5 | H15: － | I15: {=_xlfn.XLOOKUP(A15,[1]第二次落點分析!$B:$B,[1]第二次落點分析!$C:$H,"")} -> 11 | J15: 8 | K15: 4 | L15: 9 | M15: 8 | N15: － | O15: {=_xlfn.XLOOKUP(A15,'[1]113學測'!$B:$B,'[1]113學測'!$C:$H,"")} -> 12 | P15: 8 | Q15: 6 | R15: 8 | S15: 9 | T15: 12
A16: 紀承亨 | B16: 復興高中 | C16: 理組 | D16: {=_xlfn.XLOOKUP(A16,'[1]第一次落點分析 '!$B:$B,'[1]第一次落點分析 '!$C:$G,"")} -> 8 | E16: 3 | F16: 6 | G16: 6 | H16: － | I16: {=_xlfn.XLOOKUP(A16,[1]第二次落點分析!$B:$B,[1]第二次落點分析!$C:$H,"")} -> 11 | J16: 3 | K16: 5 | L16: 8 | M16: 7 | N16: － | O16: {=_xlfn.XLOOKUP(A16,'[1]113學測'!$B:$B,'[1]113學測'!$C:$H,"")} -> 8 | P16: 3 | Q16: 6 | R16: 3 | S16: 6 | T16: 11
A17: 莊雯涵 | B17: 陽明高中 | C17: 文組 | D17: {=_xlfn.XLOOKUP(A17,'[1]第一次落點分析 '!$B:$B,'[1]第一次落點分析 '!$C:$G,"")} -> 10 | E17: 3 | F17: 5 | G17: 8 | H17: － | I17: {=_xlfn.XLOOKUP(A17,[1]第二次落點分析!$B:$B,[1]第二次落點分析!$C:$H,"")} -> 10 | J17: 5 | K17: 5 | L17: 10 | M17: 8 | N17: － | O17: {=_xlfn.XLOOKUP(A17,'[1]113學測'!$B:$B,'[1]113學測'!$C:$H,"")} -> 12 | P17: 6 | Q17: 6 | R17: 8 | S17: 8 | T17: 10
A18: 李翊宏 | B18: 泰山高中 | C18: 理組 | D18: {=_xlfn.XLOOKUP(A18,'[1]第一次落點分析 '!$B:$B,'[1]第一次落點分析 '!$C:$G,"")} -> 11 | E18: 5 | F18: 9 | G18: 7 | H18: 7 | I18: {=_xlfn.XLOOKUP(A18,[1]第二次落點分析!$B:$B,[1]第二次落點分析!$C:$H,"")} -> 10 | J18: 7 | K18: 7 | L18: － | M18: 7 | N18: 7 | O18: {=_xlfn.XLOOKUP(A18,'[1]113學測'!$B:$B,'[1]113學測'!$C:$H,"")} -> 7 | P18: 5 | Q18: 7 | R18: 5 | S18: 7 | T18: 6
A19: 張晏裴 | B19: 復興高中 | C19: 文組 | D19: {=_xlfn.XLOOKUP(A19,'[1]第一次落點分析 '!$B:$B,'[1]第一次落點分析 '!$C:$G,"")} -> 8 | E19: 6 | F19: 2 | G19: 0 | H19: 8 | I19: {=_xlfn.XLOOKUP(A19,[1]第二次落點分析!$B:$B,[1]第二次落點分析!$C:$H,"")} -> 11 | J19: 8 | K19: － | L19: 3 | M19: － | N19: 8 | O19: {=_xlfn.XLOOKUP(A19,'[1]113學測'!$B:$B,'[1]113學測'!$C:$H,"")} -> 0 | P19: 0 | Q19: 0 | R19: 0 | S19: 0 | T19: 0
A20: 林宥妘 | B20: 陽明高中 | C20: 文組 | D20: {=_xlfn.XLOOKUP(A20,'[1]第一次落點分析 '!$B:$B,'[1]第一次落點分析 '!$C:$G,"")} | I20: {=_xlfn.XLOOKUP(A20,[1]第二次落點分析!$B:$B,[1]第二次落點分析!$C:$H,"")} -> 11 | J20: 3 | K20: － | L20: 6 | M20: － | N20: － | O20: {=_xlfn.XLOOKUP(A20,'[1]113學測'!$B:$B,'[1]113學測'!$C:$H,"")} -> 8 | P20: 3 | Q20: 0 | R20: 5 | S20: 4 | T20: 10
A21: 李妍萱 | B21: 陽明高中 | C21: 文組 | D21: {=_xlfn.XLOOKUP(A21,'[1]第一次落點分析 '!$B:$B,'[1]第一次落點分析 '!$C:$G,"")} -> 9 | E21: 3 | F21: 4 | G21: 0 | H21: 9 | I21: {=_xlfn.XLOOKUP(A21,[1]第二次落點分析!$B:$B,[1]第二次落點分析!$C:$H,"")} -> 4 | J21: 3 | K21: － | L21: 6 | M21: － | N21: － | O21: {=_xlfn.XLOOKUP(A21,'[1]113學測'!$B:$B,'[1]113學測'!$C:$H,"")} -> 10 | P21: 4 | Q21: 0 | R21: 6 | S21: 6 | T21: 9
A22: 楊景泓 | B22: 陽明高中 | C22: 理組 | D22: {=_xlfn.XLOOKUP(A22,'[1]第一次落點分析 '!$B:$B,'[1]第一次落點分析 '!$C:$G,"")} -> 10 | E22: 6 | F22: 7 | G22: 9 | H22: － | I22: {=_xlfn.XLOOKUP(A22,[1]第二次落點分析!$B:$B,[1]第二次落點分析!$C:$H,"")} -> 10 | J22: 5 | K22: 6 | L22: － | M22: 9 | N22: － | O22: {=_xlfn.XLOOKUP(A22,'[1]113學測'!$B:$B,'[1]113學測'!$C:$H,"")} -> 9 | P22: 5 | Q22: 5 | R22: 5 | S22: 8 | T22: 10
A23: 陳奕安 | B23: 內湖高中 | C23: 文組 | D23: {=_xlfn.XLOOKUP(A23,'[1]第一次落點分析 '!$B:$B,'[1]第一次落點分析 '!$C:$G,"")} -> 11 | E23: 11 | F23: 8 | G23: － | H23: 12 | I23: {=_xlfn.XLOOKUP(A23,[1]第二次落點分析!$B:$B,[1]第二次落點分析!$C:$H,"")} -> 11 | J23: 11 | K23: 7 | L23: 10 | M23: － | N23: 13 | O23: {=_xlfn.XLOOKUP(A23,'[1]113學測'!$B:$B,'[1]113學測'!$C:$H,"")} -> 11 | P23: 9 | Q23: 6 | R23: 7 | S23: 0 | T23: 12
A24: 林祐漢 | B24: 大安高工 | C24: 文組 | D24: {=_xlfn.XLOOKUP(A24,'[1]第一次落點分析 '!$B:$B,'[1]第一次落點分析 '!$C:$G,"")} -> 9 | E24: 4 | F24: 6 | G24: 4 | H24: 8 | I24: {=_xlfn.XLOOKUP(A24,[1]第二次落點分析!$B:$B,[1]第二次落點分析!$C:$H,"")} -> 12 | J24: 5 | K24: 5 | L24: 9 | M24: 7 | N24: 13 | O24: {=_xlfn.XLOOKUP(A24,'[1]113學測'!$B:$B,'[1]113學測'!$C:$H,"")} -> 10 | P24: 4 | Q24: 7 | R24: 8 | S24: 7 | T24: 15
A25: 鄭乃瑗 | B25: 百齡高中 | C25: 文組 | D25: {=_xlfn.XLOOKUP(A25,'[2]第一次落點分析 '!$B:$B,'[2]第一次落點分析 '!$C:$G,"")} -> 13 | E25: 5 | F25: 5 | G25: － | H25: 14 | I25: {=_xlfn.XLOOKUP(A25,[2]第二次落點分析!$B:$B,[2]第二次落點分析!$C:$H,"")} -> 12 | J25: 3 | K25: 2 | L25: 8 | M25: － | N25: 11 | O25: 11 | P25: 4 | Q25: 3 | R25: 6 | S25: X | T25: 12
A26: 周士凱 | B26: 大直高中 | C26: 理組 | D26: {=_xlfn.XLOOKUP(A26,'[2]第一次落點分析 '!$B:$B,'[2]第一次落點分析 '!$C:$G,"")} -> 9 | E26: 9 | F26: 13 | G26: 9 | H26: 0 | I26: {=_xlfn.XLOOKUP(A26,[2]第二次落點分析!$B:$B,[2]第二次落點分析!$C:$H,"")} -> 10 | J26: 9 | K26: 9 | L26: 8 | M26: 8 | N26: 8 | O26: 10 | P26: 9 | Q26: 6 | R26: 12 | S26: 12 | T26: 10
A27: 蔡宗霖 | B27: 中正高中 | C27: 理組 | D27: {=_xlfn.XLOOKUP(A27,'[2]第一次落點分析 '!$B:$B,'[2]第一次落點分析 '!$C:$G,"")} -> 11 | E27: 9 | F27: 11 | G27: 7 | H27: 9 | I27: {=_xlfn.XLOOKUP(A27,[2]第二次落點分析!$B:$B,[2]第二次落點分析!$C:$H,"")} -> 11 | J27: 9 | K27: 10 | L27: 9 | M27: 9 | N27: 8 | O27: 9 | P27: 10 | Q27: 12 | R27: 13 | S27: 11 | T27: 9
A28: 何潔瑜 | B28: 麗山高中 | C28: 理組 | D28: {=_xlfn.XLOOKUP(A28,'[2]第一次落點分析 '!$B:$B,'[2]第一次落點分析 '!$C:$G,"")} -> 11 | E28: 9 | F28: 10 | G28: 10 | H28: 9 | I28: {=_xlfn.XLOOKUP(A28,[2]第二次落點分析!$B:$B,[2]第二次落點分析!$C:$H,"")} -> 12 | J28: 8 | K28: 9 | L28: 4 | M28: 7 | N28: 0 | O28: 11 | P28: 8 | Q28: 8 | R28: 12 | S28: 11 | T28: 10
A29: 沈佑勳 | B29: 中崙高中 | C29: 理組 | D29: {=_xlfn.XLOOKUP(A29,'[2]第一次落點分析 '!$B:$B,'[2]第一次落點分析 '!$C:$G,"")} -> 12 | E29: 12 | F29: 11 | G29: 10 | H29: － | I29: {=_xlfn.XLOOKUP(A29,[2]第二次落點分析!$B:$B,[2]第二次落點分析!$C:$H,"")} -> 12 | J29: 14 | K29: 10 | L29: 11 | M29: 12 | N29: － | O29: 11 | P29: 14 | Q29: 12 | R29: 12 | S29: 13 | T29: 10
A30: 紀慶宥 | B30: 中崙高中 | C30: 理組 | D30: {=_xlfn.XLOOKUP(A30,'[2]第一次落點分析 '!$B:$B,'[2]第一次落點分析 '!$C:$G,"")} -> 9 | E30: 10 | F30: 10 | G30: 10 | H30: 0 | I30: {=_xlfn.XLOOKUP(A30,[2]第二次落點分析!$B:$B,[2]第二次落點分析!$C:$H,"")} -> 9 | J30: 9 | K30: 8 | L30: 0 | M30: 11 | N30: 0 | O30: 12 | P30: 10 | Q30: 6 | R30: 6 | S30: 9 | T30: X
A31: 孟容瑄 | B31: 松山高中 | C31: 理組 | D31: {=_xlfn.XLOOKUP(A31,'[2]第一次落點分析 '!$B:$B,'[2]第一次落點分析 '!$C:$G,"")} -> 15 | E31: 10 | F31: 10 | G31: 12 | H31: 13 | I31: {=_xlfn.XLOOKUP(A31,[2]第二次落點分析!$B:$B,[2]第二次落點分析!$C:$H,"")} -> 12 | J31: 11 | K31: 10 | L31: 7 | M31: 11 | N31: 13 | O31: 13 | P31: 11 | Q31: 9 | R31: 10 | S31: 11 | T31: 12
A32: 顧家綺 | B32: 百齡高中 | C32: 文組 | D32: {=_xlfn.XLOOKUP(A32,'[2]第一次落點分析 '!$B:$B,'[2]第一次落點分析 '!$C:$G,"")} -> 10 | E32: 4 | F32: 9 | G32: 9 | H32: 10 | I32: {=_xlfn.XLOOKUP(A32,[2]第二次落點分析!$B:$B,[2]第二次落點分析!$C:$H,"")} -> 10 | J32: 5 | K32: 6 | L32: 0 | M32: 6 | N32: 8 | O32: 7 | P32: 5 | Q32: 3 | R32: 5 | S32: 8 | T32: 11
A33: 張秦瑜 | B33: 竹圍高中 | C33: 理組 | D33: {=_xlfn.XLOOKUP(A33,'[2]第一次落點分析 '!$B:$B,'[2]第一次落點分析 '!$C:$G,"")} -> 9 | E33: 6 | F33: 8 | G33: 8 | H33: 0 | I33: {=_xlfn.XLOOKUP(A33,[2]第二次落點分析!$B:$B,[2]第二次落點分析!$C:$H,"")} -> 8 | J33: 7 | K33: 10 | L33: 10 | M33: 10 | N33: 0 | O33: 8 | P33: 5 | Q33: 6 | R33: X | S33: 8 | T33: X
A34: 楊竣名 | B34: 百齡高中 | C34: 理組 | D34: {=_xlfn.XLOOKUP(A34,'[2]第一次落點分析 '!$B:$B,'[2]第一次落點分析 '!$C:$G,"")} -> 11 | E34: 8 | F34: 8 | G34: 6 | H34: 0 | I34: {=_xlfn.XLOOKUP(A34,[2]第二次落點分析!$B:$B,[2]第二次落點分析!$C:$H,"")} -> 12 | J34: 7 | K34: 9 | L34: 0 | M34: 9 | N34: 0 | O34: 11 | P34: 10 | Q34: 11 | R34: 13 | S34: 10 | T34: 12
A35: 陳宥楠 | B35: 百齡高中 | C35: 理組 | D35: {=_xlfn.XLOOKUP(A35,'[2]第一次落點分析 '!$B:$B,'[2]第一次落點分析 '!$C:$G,"")} -> 11 | E35: 7 | F35: 10 | G35: 8 | H35: 9 | I35: {=_xlfn.XLOOKUP(A35,[2]第二次落點分析!$B:$B,[2]第二次落點分析!$C:$H,"")} -> 10 | J35: 5 | K35: 10 | L35: 7 | M35: 10 | N35: 0 | O35: 10 | P35: 5 | Q35: 11 | R35: 9 | S35: 14 | T35: 8
A36: 何宜頡 | B36: 陽明高中 | C36: 文組 | D36: {=_xlfn.XLOOKUP(A36,'[2]第一次落點分析 '!$B:$B,'[2]第一次落點分析 '!$C:$G,"")} -> 13 | E36: 9 | F36: 7 | G36: 0 | H36: 12 | I36: {=_xlfn.XLOOKUP(A36,[2]第二次落點分析!$B:$B,[2]第二次落點分析!$C:$H,"")} -> 11 | J36: 11 | K36: 4 | L36: 7 | M36: 0 | N36: 12 | O36: 10 | P36: 9 | Q36: 6 | R36: 6 | S36: X | T36: 13
A37: 陳思妤 | B37: 大同高中 | C37: 理組 | D37: {=_xlfn.XLOOKUP(A37,'[2]第一次落點分析 '!$B:$B,'[2]第一次落點分析 '!$C:$G,"")} -> 13 | E37: 14 | F37: 14 | G37: 8 | H37: － | I37: {=_xlfn.XLOOKUP(A37,[2]第二次落點分析!$B:$B,[2]第二次落點分析!$C:$H,"")} -> 11 | J37: 14 | K37: 10 | L37: 9 | M37: 8 | N37: － | O37: 12 | P37: 15 | Q37: 8 | R37: 11 | S37: 11 | T37: 14
A38: 何旻臻 | B38: 成淵高中 | C38: 理組 | D38: {=_xlfn.XLOOKUP(A38,'[2]第一次落點分析 '!$B:$B,'[2]第一次落點分析 '!$C:$G,"")} -> 13 | E38: 8 | F38: 10 | G38: 11 | H38: － | I38: {=_xlfn.XLOOKUP(A38,[2]第二次落點分析!$B:$B,[2]第二次落點分析!$C:$H,"")} -> 9 | J38: 8 | K38: 5 | L38: 7 | M38: 10 | N38: 13 | O38: 13 | P38: 8 | Q38: 8 | R38: 11 | S38: 12 | T38: 14
A39: 侯育臻 | B39: 百齡高中 | C39: 理組 | D39: {=_xlfn.XLOOKUP(A39,'[2]第一次落點分析 '!$B:$B,'[2]第一次落點分析 '!$C:$G,"")} -> 8 | E39: 10 | F39: 5 | G39: 7 | H39: 9 | I39: {=_xlfn.XLOOKUP(A39,[2]第二次落點分析!$B:$B,[2]第二次落點分析!$C:$H,"")} -> 8 | J39: 8 | K39: 4 | L39: 4 | M39: 6 | N39: 8
A40: 黃毓庭 | B40: 景美女中 | C40: 理組 | D40: {=_xlfn.XLOOKUP(A40,'[2]第一次落點分析 '!$B:$B,'[2]第一次落點分析 '!$C:$G,"")} -> 5 | E40: 12 | F40: 9 | G40: 9 | H40: 9 | I40: {=_xlfn.XLOOKUP(A40,[2]第二次落點分析!$B:$B,[2]第二次落點分析!$C:$H,"")} -> 12 | J40: 8 | K40: 4 | L40: 5 | M40: 7 | N40: 11 | O40: 12 | P40: 9 | Q40: 6 | R40: 9 | S40: 8 | T40: 11
...
